2025-05-05 14:56:03,071 ERROR: Exception on /journal/edit_entry/7 [GET] [in /home/venture/.venvs/flask_env/lib/python3.11/site-packages/flask/app.py:875]
Traceback (most recent call last):
  File "/home/venture/.venvs/flask_env/lib/python3.11/site-packages/flask/app.py", line 1511, in wsgi_app
    response = self.full_dispatch_request()
               ^^^^^^^^^^^^^^^^^^^^^^^^^^^^
  File "/home/venture/.venvs/flask_env/lib/python3.11/site-packages/flask/app.py", line 919, in full_dispatch_request
    rv = self.handle_user_exception(e)
         ^^^^^^^^^^^^^^^^^^^^^^^^^^^^^
  File "/home/venture/.venvs/flask_env/lib/python3.11/site-packages/flask/app.py", line 917, in full_dispatch_request
    rv = self.dispatch_request()
         ^^^^^^^^^^^^^^^^^^^^^^^
  File "/home/venture/.venvs/flask_env/lib/python3.11/site-packages/flask/app.py", line 902, in dispatch_request
    return self.ensure_sync(self.view_functions[rule.endpoint])(**view_args)  # type: ignore[no-any-return]
           ^^^^^^^^^^^^^^^^^^^^^^^^^^^^^^^^^^^^^^^^^^^^^^^^^^^^^^^^^^^^^^^^^
  File "/home/venture/.venvs/flask_env/lib/python3.11/site-packages/flask_login/utils.py", line 290, in decorated_view
    return current_app.ensure_sync(func)(*args, **kwargs)
           ^^^^^^^^^^^^^^^^^^^^^^^^^^^^^^^^^^^^^^^^^^^^^^
  File "/home/venture/journal_app/app/journal/routes.py", line 114, in edit_entry
    return render_template(url_for('.edit_entry/<int:entry_id>'), title='Cool', form=form)
                           ^^^^^^^^^^^^^^^^^^^^^^^^^^^^^^^^^^^^^
  File "/home/venture/.venvs/flask_env/lib/python3.11/site-packages/flask/helpers.py", line 232, in url_for
    return current_app.url_for(
           ^^^^^^^^^^^^^^^^^^^^
  File "/home/venture/.venvs/flask_env/lib/python3.11/site-packages/flask/app.py", line 1121, in url_for
    return self.handle_url_build_error(error, endpoint, values)
           ^^^^^^^^^^^^^^^^^^^^^^^^^^^^^^^^^^^^^^^^^^^^^^^^^^^^
  File "/home/venture/.venvs/flask_env/lib/python3.11/site-packages/flask/app.py", line 1110, in url_for
    rv = url_adapter.build(  # type: ignore[union-attr]
         ^^^^^^^^^^^^^^^^^^^^^^^^^^^^^^^^^^^^^^^^^^^^^^
  File "/home/venture/.venvs/flask_env/lib/python3.11/site-packages/werkzeug/routing/map.py", line 924, in build
    raise BuildError(endpoint, values, method, self)
werkzeug.routing.exceptions.BuildError: Could not build url for endpoint 'journal.edit_entry/<int:entry_id>'. Did you mean 'journal.edit_entry' instead?
2025-05-05 14:59:11,467 INFO: Digital-Journal-App startup [in /home/venture/journal_app/app/__init__.py:48]
2025-05-05 14:59:12,053 ERROR: Exception on /journal/journal [GET] [in /home/venture/.venvs/flask_env/lib/python3.11/site-packages/flask/app.py:875]
Traceback (most recent call last):
  File "/home/venture/.venvs/flask_env/lib/python3.11/site-packages/flask/app.py", line 1511, in wsgi_app
    response = self.full_dispatch_request()
               ^^^^^^^^^^^^^^^^^^^^^^^^^^^^
  File "/home/venture/.venvs/flask_env/lib/python3.11/site-packages/flask/app.py", line 919, in full_dispatch_request
    rv = self.handle_user_exception(e)
         ^^^^^^^^^^^^^^^^^^^^^^^^^^^^^
  File "/home/venture/.venvs/flask_env/lib/python3.11/site-packages/flask/app.py", line 917, in full_dispatch_request
    rv = self.dispatch_request()
         ^^^^^^^^^^^^^^^^^^^^^^^
  File "/home/venture/.venvs/flask_env/lib/python3.11/site-packages/flask/app.py", line 902, in dispatch_request
    return self.ensure_sync(self.view_functions[rule.endpoint])(**view_args)  # type: ignore[no-any-return]
           ^^^^^^^^^^^^^^^^^^^^^^^^^^^^^^^^^^^^^^^^^^^^^^^^^^^^^^^^^^^^^^^^^
  File "/home/venture/.venvs/flask_env/lib/python3.11/site-packages/flask_login/utils.py", line 290, in decorated_view
    return current_app.ensure_sync(func)(*args, **kwargs)
           ^^^^^^^^^^^^^^^^^^^^^^^^^^^^^^^^^^^^^^^^^^^^^^
  File "/home/venture/journal_app/app/journal/routes.py", line 39, in journal
    return render_template('journal/journal.html', journal_entries=journal_entries)
           ^^^^^^^^^^^^^^^^^^^^^^^^^^^^^^^^^^^^^^^^^^^^^^^^^^^^^^^^^^^^^^^^^^^^^^^^
  File "/home/venture/.venvs/flask_env/lib/python3.11/site-packages/flask/templating.py", line 149, in render_template
    template = app.jinja_env.get_or_select_template(template_name_or_list)
               ^^^^^^^^^^^^^^^^^^^^^^^^^^^^^^^^^^^^^^^^^^^^^^^^^^^^^^^^^^^
  File "/home/venture/.venvs/flask_env/lib/python3.11/site-packages/jinja2/environment.py", line 1087, in get_or_select_template
    return self.get_template(template_name_or_list, parent, globals)
           ^^^^^^^^^^^^^^^^^^^^^^^^^^^^^^^^^^^^^^^^^^^^^^^^^^^^^^^^^
  File "/home/venture/.venvs/flask_env/lib/python3.11/site-packages/jinja2/environment.py", line 1016, in get_template
    return self._load_template(name, globals)
           ^^^^^^^^^^^^^^^^^^^^^^^^^^^^^^^^^^
  File "/home/venture/.venvs/flask_env/lib/python3.11/site-packages/jinja2/environment.py", line 975, in _load_template
    template = self.loader.load(self, name, self.make_globals(globals))
               ^^^^^^^^^^^^^^^^^^^^^^^^^^^^^^^^^^^^^^^^^^^^^^^^^^^^^^^^
  File "/home/venture/.venvs/flask_env/lib/python3.11/site-packages/jinja2/loaders.py", line 138, in load
    code = environment.compile(source, name, filename)
           ^^^^^^^^^^^^^^^^^^^^^^^^^^^^^^^^^^^^^^^^^^^
  File "/home/venture/.venvs/flask_env/lib/python3.11/site-packages/jinja2/environment.py", line 771, in compile
    self.handle_exception(source=source_hint)
  File "/home/venture/.venvs/flask_env/lib/python3.11/site-packages/jinja2/environment.py", line 942, in handle_exception
    raise rewrite_traceback_stack(source=source)
  File "/home/venture/journal_app/app/templates/journal/journal.html", line 17, in template
    <a href="{{ url_for('.edit_entry', entry_id='<int:the_var>) }}">edit</a>
    ^^^^^^^^^^^^^^^^^^^^^^^^^
jinja2.exceptions.TemplateSyntaxError: unexpected char "'" at 702
2025-05-05 15:00:00,449 INFO: Digital-Journal-App startup [in /home/venture/journal_app/app/__init__.py:48]
2025-05-05 15:00:02,987 ERROR: Exception on /journal/journal [GET] [in /home/venture/.venvs/flask_env/lib/python3.11/site-packages/flask/app.py:875]
Traceback (most recent call last):
  File "/home/venture/.venvs/flask_env/lib/python3.11/site-packages/flask/app.py", line 1511, in wsgi_app
    response = self.full_dispatch_request()
               ^^^^^^^^^^^^^^^^^^^^^^^^^^^^
  File "/home/venture/.venvs/flask_env/lib/python3.11/site-packages/flask/app.py", line 919, in full_dispatch_request
    rv = self.handle_user_exception(e)
         ^^^^^^^^^^^^^^^^^^^^^^^^^^^^^
  File "/home/venture/.venvs/flask_env/lib/python3.11/site-packages/flask/app.py", line 917, in full_dispatch_request
    rv = self.dispatch_request()
         ^^^^^^^^^^^^^^^^^^^^^^^
  File "/home/venture/.venvs/flask_env/lib/python3.11/site-packages/flask/app.py", line 902, in dispatch_request
    return self.ensure_sync(self.view_functions[rule.endpoint])(**view_args)  # type: ignore[no-any-return]
           ^^^^^^^^^^^^^^^^^^^^^^^^^^^^^^^^^^^^^^^^^^^^^^^^^^^^^^^^^^^^^^^^^
  File "/home/venture/.venvs/flask_env/lib/python3.11/site-packages/flask_login/utils.py", line 290, in decorated_view
    return current_app.ensure_sync(func)(*args, **kwargs)
           ^^^^^^^^^^^^^^^^^^^^^^^^^^^^^^^^^^^^^^^^^^^^^^
  File "/home/venture/journal_app/app/journal/routes.py", line 39, in journal
    return render_template('journal/journal.html', journal_entries=journal_entries)
           ^^^^^^^^^^^^^^^^^^^^^^^^^^^^^^^^^^^^^^^^^^^^^^^^^^^^^^^^^^^^^^^^^^^^^^^^
  File "/home/venture/.venvs/flask_env/lib/python3.11/site-packages/flask/templating.py", line 150, in render_template
    return _render(app, template, context)
           ^^^^^^^^^^^^^^^^^^^^^^^^^^^^^^^
  File "/home/venture/.venvs/flask_env/lib/python3.11/site-packages/flask/templating.py", line 131, in _render
    rv = template.render(context)
         ^^^^^^^^^^^^^^^^^^^^^^^^
  File "/home/venture/.venvs/flask_env/lib/python3.11/site-packages/jinja2/environment.py", line 1295, in render
    self.environment.handle_exception()
  File "/home/venture/.venvs/flask_env/lib/python3.11/site-packages/jinja2/environment.py", line 942, in handle_exception
    raise rewrite_traceback_stack(source=source)
  File "/home/venture/journal_app/app/templates/journal/journal.html", line 1, in top-level template code
    {% extends "base.html" %}
  File "/home/venture/journal_app/app/templates/base.html", line 63, in top-level template code
    {% block content %}{% endblock %}
    ^^^^^^^^^^^^^^^^^^^^^^^^^
  File "/home/venture/journal_app/app/templates/journal/journal.html", line 17, in block 'content'
    <a href="{{ url_for('.edit_entry', entry_id='item | int') }}">edit</a>
    ^^^^^^^^^^^^^^^^^^^^^^^^^
  File "/home/venture/.venvs/flask_env/lib/python3.11/site-packages/flask/app.py", line 1110, in url_for
    rv = url_adapter.build(  # type: ignore[union-attr]
         ^^^^^^^^^^^^^^^^^^^^^^^^^^^^^^^^^^^^^^^^^^^^^^
  File "/home/venture/.venvs/flask_env/lib/python3.11/site-packages/werkzeug/routing/map.py", line 922, in build
    rv = self._partial_build(endpoint, values, method, append_unknown)
         ^^^^^^^^^^^^^^^^^^^^^^^^^^^^^^^^^^^^^^^^^^^^^^^^^^^^^^^^^^^^^
  File "/home/venture/.venvs/flask_env/lib/python3.11/site-packages/werkzeug/routing/map.py", line 801, in _partial_build
    rv = self._partial_build(
         ^^^^^^^^^^^^^^^^^^^^
  File "/home/venture/.venvs/flask_env/lib/python3.11/site-packages/werkzeug/routing/map.py", line 814, in _partial_build
    build_rv = rule.build(values, append_unknown)
               ^^^^^^^^^^^^^^^^^^^^^^^^^^^^^^^^^^
  File "/home/venture/.venvs/flask_env/lib/python3.11/site-packages/werkzeug/routing/rules.py", line 850, in build
    return self._build_unknown(**values)
           ^^^^^^^^^^^^^^^^^^^^^^^^^^^^^
  File "<werkzeug routing>", line 1, in <builder:'/journal/edit_entry/<int:entry_id>'>
  File "/home/venture/.venvs/flask_env/lib/python3.11/site-packages/werkzeug/routing/converters.py", line 163, in to_url
    value_str = str(self.num_convert(value))
                    ^^^^^^^^^^^^^^^^^^^^^^^
ValueError: invalid literal for int() with base 10: 'item | int'
