2025-05-05 14:20:47,145 ERROR: Exception on /journal/edit_entry/7 [GET] [in /home/venture/.venvs/flask_env/lib/python3.11/site-packages/flask/app.py:875]
Traceback (most recent call last):
  File "/home/venture/.venvs/flask_env/lib/python3.11/site-packages/flask/app.py", line 1511, in wsgi_app
    response = self.full_dispatch_request()
               ^^^^^^^^^^^^^^^^^^^^^^^^^^^^
  File "/home/venture/.venvs/flask_env/lib/python3.11/site-packages/flask/app.py", line 919, in full_dispatch_request
    rv = self.handle_user_exception(e)
         ^^^^^^^^^^^^^^^^^^^^^^^^^^^^^
  File "/home/venture/.venvs/flask_env/lib/python3.11/site-packages/flask/app.py", line 917, in full_dispatch_request
    rv = self.dispatch_request()
         ^^^^^^^^^^^^^^^^^^^^^^^
  File "/home/venture/.venvs/flask_env/lib/python3.11/site-packages/flask/app.py", line 902, in dispatch_request
    return self.ensure_sync(self.view_functions[rule.endpoint])(**view_args)  # type: ignore[no-any-return]
           ^^^^^^^^^^^^^^^^^^^^^^^^^^^^^^^^^^^^^^^^^^^^^^^^^^^^^^^^^^^^^^^^^
  File "/home/venture/.venvs/flask_env/lib/python3.11/site-packages/flask_login/utils.py", line 290, in decorated_view
    return current_app.ensure_sync(func)(*args, **kwargs)
           ^^^^^^^^^^^^^^^^^^^^^^^^^^^^^^^^^^^^^^^^^^^^^^
  File "/home/venture/journal_app/app/journal/routes.py", line 113, in edit_entry
    return render_template(url_for('journal.edit_entry.', entry_id=entry_id))
                           ^^^^^^^^^^^^^^^^^^^^^^^^^^^^^^^^^^^^^^^^^^^^^^^^^
  File "/home/venture/.venvs/flask_env/lib/python3.11/site-packages/flask/helpers.py", line 232, in url_for
    return current_app.url_for(
           ^^^^^^^^^^^^^^^^^^^^
  File "/home/venture/.venvs/flask_env/lib/python3.11/site-packages/flask/app.py", line 1121, in url_for
    return self.handle_url_build_error(error, endpoint, values)
           ^^^^^^^^^^^^^^^^^^^^^^^^^^^^^^^^^^^^^^^^^^^^^^^^^^^^
  File "/home/venture/.venvs/flask_env/lib/python3.11/site-packages/flask/app.py", line 1110, in url_for
    rv = url_adapter.build(  # type: ignore[union-attr]
         ^^^^^^^^^^^^^^^^^^^^^^^^^^^^^^^^^^^^^^^^^^^^^^
  File "/home/venture/.venvs/flask_env/lib/python3.11/site-packages/werkzeug/routing/map.py", line 924, in build
    raise BuildError(endpoint, values, method, self)
werkzeug.routing.exceptions.BuildError: Could not build url for endpoint 'journal.edit_entry.' with values ['entry_id']. Did you mean 'journal.edit_entry' instead?
2025-05-05 14:21:35,090 INFO: Digital-Journal-App startup [in /home/venture/journal_app/app/__init__.py:48]
2025-05-05 14:21:37,419 ERROR: Exception on /journal/edit_entry/7 [GET] [in /home/venture/.venvs/flask_env/lib/python3.11/site-packages/flask/app.py:875]
Traceback (most recent call last):
  File "/home/venture/.venvs/flask_env/lib/python3.11/site-packages/flask/app.py", line 1511, in wsgi_app
    response = self.full_dispatch_request()
               ^^^^^^^^^^^^^^^^^^^^^^^^^^^^
  File "/home/venture/.venvs/flask_env/lib/python3.11/site-packages/flask/app.py", line 919, in full_dispatch_request
    rv = self.handle_user_exception(e)
         ^^^^^^^^^^^^^^^^^^^^^^^^^^^^^
  File "/home/venture/.venvs/flask_env/lib/python3.11/site-packages/flask/app.py", line 917, in full_dispatch_request
    rv = self.dispatch_request()
         ^^^^^^^^^^^^^^^^^^^^^^^
  File "/home/venture/.venvs/flask_env/lib/python3.11/site-packages/flask/app.py", line 902, in dispatch_request
    return self.ensure_sync(self.view_functions[rule.endpoint])(**view_args)  # type: ignore[no-any-return]
           ^^^^^^^^^^^^^^^^^^^^^^^^^^^^^^^^^^^^^^^^^^^^^^^^^^^^^^^^^^^^^^^^^
  File "/home/venture/.venvs/flask_env/lib/python3.11/site-packages/flask_login/utils.py", line 290, in decorated_view
    return current_app.ensure_sync(func)(*args, **kwargs)
           ^^^^^^^^^^^^^^^^^^^^^^^^^^^^^^^^^^^^^^^^^^^^^^
  File "/home/venture/journal_app/app/journal/routes.py", line 113, in edit_entry
    return render_template(url_for('edit_entry', entry_id=entry_id))
                           ^^^^^^^^^^^^^^^^^^^^^^^^^^^^^^^^^^^^^^^^
  File "/home/venture/.venvs/flask_env/lib/python3.11/site-packages/flask/helpers.py", line 232, in url_for
    return current_app.url_for(
           ^^^^^^^^^^^^^^^^^^^^
  File "/home/venture/.venvs/flask_env/lib/python3.11/site-packages/flask/app.py", line 1121, in url_for
    return self.handle_url_build_error(error, endpoint, values)
           ^^^^^^^^^^^^^^^^^^^^^^^^^^^^^^^^^^^^^^^^^^^^^^^^^^^^
  File "/home/venture/.venvs/flask_env/lib/python3.11/site-packages/flask/app.py", line 1110, in url_for
    rv = url_adapter.build(  # type: ignore[union-attr]
         ^^^^^^^^^^^^^^^^^^^^^^^^^^^^^^^^^^^^^^^^^^^^^^
  File "/home/venture/.venvs/flask_env/lib/python3.11/site-packages/werkzeug/routing/map.py", line 924, in build
    raise BuildError(endpoint, values, method, self)
werkzeug.routing.exceptions.BuildError: Could not build url for endpoint 'edit_entry' with values ['entry_id']. Did you mean 'journal.edit_entry' instead?
2025-05-05 14:21:49,194 INFO: Digital-Journal-App startup [in /home/venture/journal_app/app/__init__.py:48]
2025-05-05 14:21:54,730 ERROR: Exception on /journal/edit_entry/7 [GET] [in /home/venture/.venvs/flask_env/lib/python3.11/site-packages/flask/app.py:875]
Traceback (most recent call last):
  File "/home/venture/.venvs/flask_env/lib/python3.11/site-packages/flask/app.py", line 1511, in wsgi_app
    response = self.full_dispatch_request()
               ^^^^^^^^^^^^^^^^^^^^^^^^^^^^
  File "/home/venture/.venvs/flask_env/lib/python3.11/site-packages/flask/app.py", line 919, in full_dispatch_request
    rv = self.handle_user_exception(e)
         ^^^^^^^^^^^^^^^^^^^^^^^^^^^^^
  File "/home/venture/.venvs/flask_env/lib/python3.11/site-packages/flask/app.py", line 917, in full_dispatch_request
    rv = self.dispatch_request()
         ^^^^^^^^^^^^^^^^^^^^^^^
  File "/home/venture/.venvs/flask_env/lib/python3.11/site-packages/flask/app.py", line 902, in dispatch_request
    return self.ensure_sync(self.view_functions[rule.endpoint])(**view_args)  # type: ignore[no-any-return]
           ^^^^^^^^^^^^^^^^^^^^^^^^^^^^^^^^^^^^^^^^^^^^^^^^^^^^^^^^^^^^^^^^^
  File "/home/venture/.venvs/flask_env/lib/python3.11/site-packages/flask_login/utils.py", line 290, in decorated_view
    return current_app.ensure_sync(func)(*args, **kwargs)
           ^^^^^^^^^^^^^^^^^^^^^^^^^^^^^^^^^^^^^^^^^^^^^^
  File "/home/venture/journal_app/app/journal/routes.py", line 113, in edit_entry
    return render_template(url_for('journal.edit_entry', entry_id=entry_id))
           ^^^^^^^^^^^^^^^^^^^^^^^^^^^^^^^^^^^^^^^^^^^^^^^^^^^^^^^^^^^^^^^^^
  File "/home/venture/.venvs/flask_env/lib/python3.11/site-packages/flask/templating.py", line 149, in render_template
    template = app.jinja_env.get_or_select_template(template_name_or_list)
               ^^^^^^^^^^^^^^^^^^^^^^^^^^^^^^^^^^^^^^^^^^^^^^^^^^^^^^^^^^^
  File "/home/venture/.venvs/flask_env/lib/python3.11/site-packages/jinja2/environment.py", line 1087, in get_or_select_template
    return self.get_template(template_name_or_list, parent, globals)
           ^^^^^^^^^^^^^^^^^^^^^^^^^^^^^^^^^^^^^^^^^^^^^^^^^^^^^^^^^
  File "/home/venture/.venvs/flask_env/lib/python3.11/site-packages/jinja2/environment.py", line 1016, in get_template
    return self._load_template(name, globals)
           ^^^^^^^^^^^^^^^^^^^^^^^^^^^^^^^^^^
  File "/home/venture/.venvs/flask_env/lib/python3.11/site-packages/jinja2/environment.py", line 975, in _load_template
    template = self.loader.load(self, name, self.make_globals(globals))
               ^^^^^^^^^^^^^^^^^^^^^^^^^^^^^^^^^^^^^^^^^^^^^^^^^^^^^^^^
  File "/home/venture/.venvs/flask_env/lib/python3.11/site-packages/jinja2/loaders.py", line 126, in load
    source, filename, uptodate = self.get_source(environment, name)
                                 ^^^^^^^^^^^^^^^^^^^^^^^^^^^^^^^^^^
  File "/home/venture/.venvs/flask_env/lib/python3.11/site-packages/flask/templating.py", line 65, in get_source
    return self._get_source_fast(environment, template)
           ^^^^^^^^^^^^^^^^^^^^^^^^^^^^^^^^^^^^^^^^^^^^
  File "/home/venture/.venvs/flask_env/lib/python3.11/site-packages/flask/templating.py", line 99, in _get_source_fast
    raise TemplateNotFound(template)
jinja2.exceptions.TemplateNotFound: /journal/edit_entry/7
2025-05-05 14:22:22,384 INFO: Digital-Journal-App startup [in /home/venture/journal_app/app/__init__.py:48]
