2025-05-05 14:11:28,925 ERROR: Exception on /journal/journal [GET] [in /home/venture/.venvs/flask_env/lib/python3.11/site-packages/flask/app.py:875]
Traceback (most recent call last):
  File "/home/venture/.venvs/flask_env/lib/python3.11/site-packages/flask/app.py", line 1511, in wsgi_app
    response = self.full_dispatch_request()
               ^^^^^^^^^^^^^^^^^^^^^^^^^^^^
  File "/home/venture/.venvs/flask_env/lib/python3.11/site-packages/flask/app.py", line 919, in full_dispatch_request
    rv = self.handle_user_exception(e)
         ^^^^^^^^^^^^^^^^^^^^^^^^^^^^^
  File "/home/venture/.venvs/flask_env/lib/python3.11/site-packages/flask/app.py", line 917, in full_dispatch_request
    rv = self.dispatch_request()
         ^^^^^^^^^^^^^^^^^^^^^^^
  File "/home/venture/.venvs/flask_env/lib/python3.11/site-packages/flask/app.py", line 902, in dispatch_request
    return self.ensure_sync(self.view_functions[rule.endpoint])(**view_args)  # type: ignore[no-any-return]
           ^^^^^^^^^^^^^^^^^^^^^^^^^^^^^^^^^^^^^^^^^^^^^^^^^^^^^^^^^^^^^^^^^
  File "/home/venture/.venvs/flask_env/lib/python3.11/site-packages/flask_login/utils.py", line 290, in decorated_view
    return current_app.ensure_sync(func)(*args, **kwargs)
           ^^^^^^^^^^^^^^^^^^^^^^^^^^^^^^^^^^^^^^^^^^^^^^
  File "/home/venture/journal_app/app/journal/routes.py", line 39, in journal
    return render_template('journal/journal.html', journal_entries=journal_entries)
           ^^^^^^^^^^^^^^^^^^^^^^^^^^^^^^^^^^^^^^^^^^^^^^^^^^^^^^^^^^^^^^^^^^^^^^^^
  File "/home/venture/.venvs/flask_env/lib/python3.11/site-packages/flask/templating.py", line 150, in render_template
    return _render(app, template, context)
           ^^^^^^^^^^^^^^^^^^^^^^^^^^^^^^^
  File "/home/venture/.venvs/flask_env/lib/python3.11/site-packages/flask/templating.py", line 131, in _render
    rv = template.render(context)
         ^^^^^^^^^^^^^^^^^^^^^^^^
  File "/home/venture/.venvs/flask_env/lib/python3.11/site-packages/jinja2/environment.py", line 1295, in render
    self.environment.handle_exception()
  File "/home/venture/.venvs/flask_env/lib/python3.11/site-packages/jinja2/environment.py", line 942, in handle_exception
    raise rewrite_traceback_stack(source=source)
  File "/home/venture/journal_app/app/templates/journal/journal.html", line 1, in top-level template code
    {% extends "base.html" %}
  File "/home/venture/journal_app/app/templates/base.html", line 63, in top-level template code
    {% block content %}{% endblock %}
    ^^^^^^^^^^^^^^^^^^^^^^^^^
  File "/home/venture/journal_app/app/templates/journal/journal.html", line 17, in block 'content'
    <a href="{{ redirect(url_for('journal.edit_entry', entry_id=the_var)) }}">edit</a>
    ^^^^^^^^^^^^^^^^^^^^^^^^^
  File "/home/venture/.venvs/flask_env/lib/python3.11/site-packages/jinja2/utils.py", line 92, in from_obj
    if hasattr(obj, "jinja_pass_arg"):
       ^^^^^^^^^^^^^^^^^^^^^^^^^^^^^^
jinja2.exceptions.UndefinedError: 'redirect' is undefined
2025-05-05 14:12:33,906 INFO: Digital-Journal-App startup [in /home/venture/journal_app/app/__init__.py:48]
2025-05-05 14:13:01,506 INFO: Digital-Journal-App startup [in /home/venture/journal_app/app/__init__.py:48]
2025-05-05 14:13:36,289 INFO: Digital-Journal-App startup [in /home/venture/journal_app/app/__init__.py:48]
2025-05-05 14:13:40,284 ERROR: Exception on /journal/edit_entry/7 [GET] [in /home/venture/.venvs/flask_env/lib/python3.11/site-packages/flask/app.py:875]
Traceback (most recent call last):
  File "/home/venture/.venvs/flask_env/lib/python3.11/site-packages/flask/app.py", line 1511, in wsgi_app
    response = self.full_dispatch_request()
               ^^^^^^^^^^^^^^^^^^^^^^^^^^^^
  File "/home/venture/.venvs/flask_env/lib/python3.11/site-packages/flask/app.py", line 919, in full_dispatch_request
    rv = self.handle_user_exception(e)
         ^^^^^^^^^^^^^^^^^^^^^^^^^^^^^
  File "/home/venture/.venvs/flask_env/lib/python3.11/site-packages/flask/app.py", line 917, in full_dispatch_request
    rv = self.dispatch_request()
         ^^^^^^^^^^^^^^^^^^^^^^^
  File "/home/venture/.venvs/flask_env/lib/python3.11/site-packages/flask/app.py", line 902, in dispatch_request
    return self.ensure_sync(self.view_functions[rule.endpoint])(**view_args)  # type: ignore[no-any-return]
           ^^^^^^^^^^^^^^^^^^^^^^^^^^^^^^^^^^^^^^^^^^^^^^^^^^^^^^^^^^^^^^^^^
  File "/home/venture/.venvs/flask_env/lib/python3.11/site-packages/flask_login/utils.py", line 290, in decorated_view
    return current_app.ensure_sync(func)(*args, **kwargs)
           ^^^^^^^^^^^^^^^^^^^^^^^^^^^^^^^^^^^^^^^^^^^^^^
  File "/home/venture/journal_app/app/journal/routes.py", line 113, in edit_entry
    return redirect('journal/edit_entry.html', form=form)
           ^^^^^^^^
NameError: name 'redirect' is not defined
2025-05-05 14:13:48,571 ERROR: Exception on /journal/edit_entry/7 [GET] [in /home/venture/.venvs/flask_env/lib/python3.11/site-packages/flask/app.py:875]
Traceback (most recent call last):
  File "/home/venture/.venvs/flask_env/lib/python3.11/site-packages/flask/app.py", line 1511, in wsgi_app
    response = self.full_dispatch_request()
               ^^^^^^^^^^^^^^^^^^^^^^^^^^^^
  File "/home/venture/.venvs/flask_env/lib/python3.11/site-packages/flask/app.py", line 919, in full_dispatch_request
    rv = self.handle_user_exception(e)
         ^^^^^^^^^^^^^^^^^^^^^^^^^^^^^
  File "/home/venture/.venvs/flask_env/lib/python3.11/site-packages/flask/app.py", line 917, in full_dispatch_request
    rv = self.dispatch_request()
         ^^^^^^^^^^^^^^^^^^^^^^^
  File "/home/venture/.venvs/flask_env/lib/python3.11/site-packages/flask/app.py", line 902, in dispatch_request
    return self.ensure_sync(self.view_functions[rule.endpoint])(**view_args)  # type: ignore[no-any-return]
           ^^^^^^^^^^^^^^^^^^^^^^^^^^^^^^^^^^^^^^^^^^^^^^^^^^^^^^^^^^^^^^^^^
  File "/home/venture/.venvs/flask_env/lib/python3.11/site-packages/flask_login/utils.py", line 290, in decorated_view
    return current_app.ensure_sync(func)(*args, **kwargs)
           ^^^^^^^^^^^^^^^^^^^^^^^^^^^^^^^^^^^^^^^^^^^^^^
  File "/home/venture/journal_app/app/journal/routes.py", line 113, in edit_entry
    return redirect('journal/edit_entry.html', form=form)
           ^^^^^^^^
NameError: name 'redirect' is not defined
2025-05-05 14:14:08,236 INFO: Digital-Journal-App startup [in /home/venture/journal_app/app/__init__.py:48]
2025-05-05 14:14:11,390 ERROR: Exception on /journal/edit_entry/7 [GET] [in /home/venture/.venvs/flask_env/lib/python3.11/site-packages/flask/app.py:875]
Traceback (most recent call last):
  File "/home/venture/.venvs/flask_env/lib/python3.11/site-packages/flask/app.py", line 1511, in wsgi_app
    response = self.full_dispatch_request()
               ^^^^^^^^^^^^^^^^^^^^^^^^^^^^
  File "/home/venture/.venvs/flask_env/lib/python3.11/site-packages/flask/app.py", line 919, in full_dispatch_request
    rv = self.handle_user_exception(e)
         ^^^^^^^^^^^^^^^^^^^^^^^^^^^^^
  File "/home/venture/.venvs/flask_env/lib/python3.11/site-packages/flask/app.py", line 917, in full_dispatch_request
    rv = self.dispatch_request()
         ^^^^^^^^^^^^^^^^^^^^^^^
  File "/home/venture/.venvs/flask_env/lib/python3.11/site-packages/flask/app.py", line 902, in dispatch_request
    return self.ensure_sync(self.view_functions[rule.endpoint])(**view_args)  # type: ignore[no-any-return]
           ^^^^^^^^^^^^^^^^^^^^^^^^^^^^^^^^^^^^^^^^^^^^^^^^^^^^^^^^^^^^^^^^^
  File "/home/venture/.venvs/flask_env/lib/python3.11/site-packages/flask_login/utils.py", line 290, in decorated_view
    return current_app.ensure_sync(func)(*args, **kwargs)
           ^^^^^^^^^^^^^^^^^^^^^^^^^^^^^^^^^^^^^^^^^^^^^^
  File "/home/venture/journal_app/app/journal/routes.py", line 113, in edit_entry
    return redirect('journal/edit_entry.html', form=form)
           ^^^^^^^^^^^^^^^^^^^^^^^^^^^^^^^^^^^^^^^^^^^^^^
TypeError: redirect() got an unexpected keyword argument 'form'
2025-05-05 14:14:46,981 INFO: Digital-Journal-App startup [in /home/venture/journal_app/app/__init__.py:48]
2025-05-05 14:14:49,302 ERROR: Exception on /journal/edit_entry/7 [GET] [in /home/venture/.venvs/flask_env/lib/python3.11/site-packages/flask/app.py:875]
Traceback (most recent call last):
  File "/home/venture/.venvs/flask_env/lib/python3.11/site-packages/flask/app.py", line 1511, in wsgi_app
    response = self.full_dispatch_request()
               ^^^^^^^^^^^^^^^^^^^^^^^^^^^^
  File "/home/venture/.venvs/flask_env/lib/python3.11/site-packages/flask/app.py", line 919, in full_dispatch_request
    rv = self.handle_user_exception(e)
         ^^^^^^^^^^^^^^^^^^^^^^^^^^^^^
  File "/home/venture/.venvs/flask_env/lib/python3.11/site-packages/flask/app.py", line 917, in full_dispatch_request
    rv = self.dispatch_request()
         ^^^^^^^^^^^^^^^^^^^^^^^
  File "/home/venture/.venvs/flask_env/lib/python3.11/site-packages/flask/app.py", line 902, in dispatch_request
    return self.ensure_sync(self.view_functions[rule.endpoint])(**view_args)  # type: ignore[no-any-return]
           ^^^^^^^^^^^^^^^^^^^^^^^^^^^^^^^^^^^^^^^^^^^^^^^^^^^^^^^^^^^^^^^^^
  File "/home/venture/.venvs/flask_env/lib/python3.11/site-packages/flask_login/utils.py", line 290, in decorated_view
    return current_app.ensure_sync(func)(*args, **kwargs)
           ^^^^^^^^^^^^^^^^^^^^^^^^^^^^^^^^^^^^^^^^^^^^^^
  File "/home/venture/journal_app/app/journal/routes.py", line 113, in edit_entry
    return redirect('journal/edit_entry.html', this_entry_id=this_entry_id)
                                                             ^^^^^^^^^^^^^
NameError: name 'this_entry_id' is not defined
2025-05-05 14:15:08,380 INFO: Digital-Journal-App startup [in /home/venture/journal_app/app/__init__.py:48]
