2025-05-10 03:06:03,438 ERROR: Exception on /journal/journal/ [GET] [in /home/venture/.venvs/flask_env/lib/python3.11/site-packages/flask/app.py:875]
Traceback (most recent call last):
  File "/home/venture/.venvs/flask_env/lib/python3.11/site-packages/flask/app.py", line 1511, in wsgi_app
    response = self.full_dispatch_request()
               ^^^^^^^^^^^^^^^^^^^^^^^^^^^^
  File "/home/venture/.venvs/flask_env/lib/python3.11/site-packages/flask/app.py", line 919, in full_dispatch_request
    rv = self.handle_user_exception(e)
         ^^^^^^^^^^^^^^^^^^^^^^^^^^^^^
  File "/home/venture/.venvs/flask_env/lib/python3.11/site-packages/flask/app.py", line 917, in full_dispatch_request
    rv = self.dispatch_request()
         ^^^^^^^^^^^^^^^^^^^^^^^
  File "/home/venture/.venvs/flask_env/lib/python3.11/site-packages/flask/app.py", line 902, in dispatch_request
    return self.ensure_sync(self.view_functions[rule.endpoint])(**view_args)  # type: ignore[no-any-return]
           ^^^^^^^^^^^^^^^^^^^^^^^^^^^^^^^^^^^^^^^^^^^^^^^^^^^^^^^^^^^^^^^^^
  File "/home/venture/.venvs/flask_env/lib/python3.11/site-packages/flask_login/utils.py", line 290, in decorated_view
    return current_app.ensure_sync(func)(*args, **kwargs)
           ^^^^^^^^^^^^^^^^^^^^^^^^^^^^^^^^^^^^^^^^^^^^^^
  File "/home/venture/Digital-Time-Capsule/journal_app/app/journal/routes.py", line 63, in journal
    return render_template('journal/journal.html', journal_entries=journal_entries)
           ^^^^^^^^^^^^^^^^^^^^^^^^^^^^^^^^^^^^^^^^^^^^^^^^^^^^^^^^^^^^^^^^^^^^^^^^
  File "/home/venture/.venvs/flask_env/lib/python3.11/site-packages/flask/templating.py", line 150, in render_template
    return _render(app, template, context)
           ^^^^^^^^^^^^^^^^^^^^^^^^^^^^^^^
  File "/home/venture/.venvs/flask_env/lib/python3.11/site-packages/flask/templating.py", line 131, in _render
    rv = template.render(context)
         ^^^^^^^^^^^^^^^^^^^^^^^^
  File "/home/venture/.venvs/flask_env/lib/python3.11/site-packages/jinja2/environment.py", line 1295, in render
    self.environment.handle_exception()
  File "/home/venture/.venvs/flask_env/lib/python3.11/site-packages/jinja2/environment.py", line 942, in handle_exception
    raise rewrite_traceback_stack(source=source)
  File "/home/venture/Digital-Time-Capsule/journal_app/app/templates/journal/journal.html", line 1, in top-level template code
    {% extends "base.html" %}
  File "/home/venture/Digital-Time-Capsule/journal_app/app/templates/base.html", line 63, in top-level template code
    {% block content %}{% endblock %}
    ^^^^^^^^^^^^^^^^^^^^^^^^^
  File "/home/venture/Digital-Time-Capsule/journal_app/app/templates/journal/journal.html", line 11, in block 'content'
    {% set filePath = journal_entry[item].image_path.replace('static/', '')  %}
    ^^^^^^^^^^^^^^^^^^^^^^^^^
  File "/home/venture/.venvs/flask_env/lib/python3.11/site-packages/jinja2/environment.py", line 490, in getattr
    return getattr(obj, attribute)
           ^^^^^^^^^^^^^^^^^^^^^^^
jinja2.exceptions.UndefinedError: 'dict object' has no attribute 'image_path'
2025-05-10 03:06:16,962 ERROR: Exception on /journal/journal/ [GET] [in /home/venture/.venvs/flask_env/lib/python3.11/site-packages/flask/app.py:875]
Traceback (most recent call last):
  File "/home/venture/.venvs/flask_env/lib/python3.11/site-packages/flask/app.py", line 1511, in wsgi_app
    response = self.full_dispatch_request()
               ^^^^^^^^^^^^^^^^^^^^^^^^^^^^
  File "/home/venture/.venvs/flask_env/lib/python3.11/site-packages/flask/app.py", line 919, in full_dispatch_request
    rv = self.handle_user_exception(e)
         ^^^^^^^^^^^^^^^^^^^^^^^^^^^^^
  File "/home/venture/.venvs/flask_env/lib/python3.11/site-packages/flask/app.py", line 917, in full_dispatch_request
    rv = self.dispatch_request()
         ^^^^^^^^^^^^^^^^^^^^^^^
  File "/home/venture/.venvs/flask_env/lib/python3.11/site-packages/flask/app.py", line 902, in dispatch_request
    return self.ensure_sync(self.view_functions[rule.endpoint])(**view_args)  # type: ignore[no-any-return]
           ^^^^^^^^^^^^^^^^^^^^^^^^^^^^^^^^^^^^^^^^^^^^^^^^^^^^^^^^^^^^^^^^^
  File "/home/venture/.venvs/flask_env/lib/python3.11/site-packages/flask_login/utils.py", line 290, in decorated_view
    return current_app.ensure_sync(func)(*args, **kwargs)
           ^^^^^^^^^^^^^^^^^^^^^^^^^^^^^^^^^^^^^^^^^^^^^^
  File "/home/venture/Digital-Time-Capsule/journal_app/app/journal/routes.py", line 63, in journal
    return render_template('journal/journal.html', journal_entries=journal_entries)
           ^^^^^^^^^^^^^^^^^^^^^^^^^^^^^^^^^^^^^^^^^^^^^^^^^^^^^^^^^^^^^^^^^^^^^^^^
  File "/home/venture/.venvs/flask_env/lib/python3.11/site-packages/flask/templating.py", line 150, in render_template
    return _render(app, template, context)
           ^^^^^^^^^^^^^^^^^^^^^^^^^^^^^^^
  File "/home/venture/.venvs/flask_env/lib/python3.11/site-packages/flask/templating.py", line 131, in _render
    rv = template.render(context)
         ^^^^^^^^^^^^^^^^^^^^^^^^
  File "/home/venture/.venvs/flask_env/lib/python3.11/site-packages/jinja2/environment.py", line 1295, in render
    self.environment.handle_exception()
  File "/home/venture/.venvs/flask_env/lib/python3.11/site-packages/jinja2/environment.py", line 942, in handle_exception
    raise rewrite_traceback_stack(source=source)
  File "/home/venture/Digital-Time-Capsule/journal_app/app/templates/journal/journal.html", line 1, in top-level template code
    {% extends "base.html" %}
  File "/home/venture/Digital-Time-Capsule/journal_app/app/templates/base.html", line 63, in top-level template code
    {% block content %}{% endblock %}
    ^^^^^^^^^^^^^^^^^^^^^^^^^
  File "/home/venture/Digital-Time-Capsule/journal_app/app/templates/journal/journal.html", line 11, in block 'content'
    {% set filePath = journal_entry[item].image_path.replace('static/', '')  %}
    ^^^^^^^^^^^^^^^^^^^^^^^^^
  File "/home/venture/.venvs/flask_env/lib/python3.11/site-packages/jinja2/environment.py", line 490, in getattr
    return getattr(obj, attribute)
           ^^^^^^^^^^^^^^^^^^^^^^^
jinja2.exceptions.UndefinedError: 'dict object' has no attribute 'image_path'
2025-05-10 03:06:19,460 ERROR: Exception on /journal/journal/ [GET] [in /home/venture/.venvs/flask_env/lib/python3.11/site-packages/flask/app.py:875]
Traceback (most recent call last):
  File "/home/venture/.venvs/flask_env/lib/python3.11/site-packages/flask/app.py", line 1511, in wsgi_app
    response = self.full_dispatch_request()
               ^^^^^^^^^^^^^^^^^^^^^^^^^^^^
  File "/home/venture/.venvs/flask_env/lib/python3.11/site-packages/flask/app.py", line 919, in full_dispatch_request
    rv = self.handle_user_exception(e)
         ^^^^^^^^^^^^^^^^^^^^^^^^^^^^^
  File "/home/venture/.venvs/flask_env/lib/python3.11/site-packages/flask/app.py", line 917, in full_dispatch_request
    rv = self.dispatch_request()
         ^^^^^^^^^^^^^^^^^^^^^^^
  File "/home/venture/.venvs/flask_env/lib/python3.11/site-packages/flask/app.py", line 902, in dispatch_request
    return self.ensure_sync(self.view_functions[rule.endpoint])(**view_args)  # type: ignore[no-any-return]
           ^^^^^^^^^^^^^^^^^^^^^^^^^^^^^^^^^^^^^^^^^^^^^^^^^^^^^^^^^^^^^^^^^
  File "/home/venture/.venvs/flask_env/lib/python3.11/site-packages/flask_login/utils.py", line 290, in decorated_view
    return current_app.ensure_sync(func)(*args, **kwargs)
           ^^^^^^^^^^^^^^^^^^^^^^^^^^^^^^^^^^^^^^^^^^^^^^
  File "/home/venture/Digital-Time-Capsule/journal_app/app/journal/routes.py", line 63, in journal
    return render_template('journal/journal.html', journal_entries=journal_entries)
           ^^^^^^^^^^^^^^^^^^^^^^^^^^^^^^^^^^^^^^^^^^^^^^^^^^^^^^^^^^^^^^^^^^^^^^^^
  File "/home/venture/.venvs/flask_env/lib/python3.11/site-packages/flask/templating.py", line 150, in render_template
    return _render(app, template, context)
           ^^^^^^^^^^^^^^^^^^^^^^^^^^^^^^^
  File "/home/venture/.venvs/flask_env/lib/python3.11/site-packages/flask/templating.py", line 131, in _render
    rv = template.render(context)
         ^^^^^^^^^^^^^^^^^^^^^^^^
  File "/home/venture/.venvs/flask_env/lib/python3.11/site-packages/jinja2/environment.py", line 1295, in render
    self.environment.handle_exception()
  File "/home/venture/.venvs/flask_env/lib/python3.11/site-packages/jinja2/environment.py", line 942, in handle_exception
    raise rewrite_traceback_stack(source=source)
  File "/home/venture/Digital-Time-Capsule/journal_app/app/templates/journal/journal.html", line 1, in top-level template code
    {% extends "base.html" %}
  File "/home/venture/Digital-Time-Capsule/journal_app/app/templates/base.html", line 63, in top-level template code
    {% block content %}{% endblock %}
    ^^^^^^^^^^^^^^^^^^^^^^^^^
  File "/home/venture/Digital-Time-Capsule/journal_app/app/templates/journal/journal.html", line 11, in block 'content'
    {% set filePath = journal_entry[item].image_path.replace('static/', '')  %}
    ^^^^^^^^^^^^^^^^^^^^^^^^^
  File "/home/venture/.venvs/flask_env/lib/python3.11/site-packages/jinja2/environment.py", line 490, in getattr
    return getattr(obj, attribute)
           ^^^^^^^^^^^^^^^^^^^^^^^
jinja2.exceptions.UndefinedError: 'dict object' has no attribute 'image_path'
