2025-05-10 03:32:46,369 INFO: Digital-Journal-App startup [in /home/venture/Digital-Time-Capsule/journal_app/app/__init__.py:59]
2025-05-10 03:32:52,147 INFO: Digital-Journal-App startup [in /home/venture/Digital-Time-Capsule/journal_app/app/__init__.py:59]
2025-05-10 03:33:46,171 INFO: Digital-Journal-App startup [in /home/venture/Digital-Time-Capsule/journal_app/app/__init__.py:59]
2025-05-10 03:33:52,944 INFO: Digital-Journal-App startup [in /home/venture/Digital-Time-Capsule/journal_app/app/__init__.py:59]
2025-05-10 04:46:53,975 INFO: Digital-Journal-App startup [in /home/venture/Digital-Time-Capsule/journal_app/app/__init__.py:59]
2025-05-10 04:52:24,123 INFO: Digital-Journal-App startup [in /home/venture/Digital-Time-Capsule/journal_app/app/__init__.py:59]
2025-05-10 05:01:07,621 INFO: Digital-Journal-App startup [in /home/venture/Digital-Time-Capsule/journal_app/app/__init__.py:59]
2025-05-10 05:01:28,160 INFO: Digital-Journal-App startup [in /home/venture/Digital-Time-Capsule/journal_app/app/__init__.py:59]
2025-05-10 05:13:42,986 INFO: Digital-Journal-App startup [in /home/venture/Digital-Time-Capsule/journal_app/app/__init__.py:59]
2025-05-10 05:21:20,861 INFO: Digital-Journal-App startup [in /home/venture/Digital-Time-Capsule/journal_app/app/__init__.py:59]
2025-05-10 05:24:45,049 INFO: Digital-Journal-App startup [in /home/venture/Digital-Time-Capsule/journal_app/app/__init__.py:59]
2025-05-10 05:24:57,418 ERROR: Exception on /journal/edit_entry/2 [POST] [in /home/venture/.venvs/flask_env/lib/python3.11/site-packages/flask/app.py:875]
Traceback (most recent call last):
  File "/home/venture/.venvs/flask_env/lib/python3.11/site-packages/flask/app.py", line 1511, in wsgi_app
    response = self.full_dispatch_request()
               ^^^^^^^^^^^^^^^^^^^^^^^^^^^^
  File "/home/venture/.venvs/flask_env/lib/python3.11/site-packages/flask/app.py", line 919, in full_dispatch_request
    rv = self.handle_user_exception(e)
         ^^^^^^^^^^^^^^^^^^^^^^^^^^^^^
  File "/home/venture/.venvs/flask_env/lib/python3.11/site-packages/flask/app.py", line 917, in full_dispatch_request
    rv = self.dispatch_request()
         ^^^^^^^^^^^^^^^^^^^^^^^
  File "/home/venture/.venvs/flask_env/lib/python3.11/site-packages/flask/app.py", line 902, in dispatch_request
    return self.ensure_sync(self.view_functions[rule.endpoint])(**view_args)  # type: ignore[no-any-return]
           ^^^^^^^^^^^^^^^^^^^^^^^^^^^^^^^^^^^^^^^^^^^^^^^^^^^^^^^^^^^^^^^^^
  File "/home/venture/.venvs/flask_env/lib/python3.11/site-packages/flask_login/utils.py", line 290, in decorated_view
    return current_app.ensure_sync(func)(*args, **kwargs)
           ^^^^^^^^^^^^^^^^^^^^^^^^^^^^^^^^^^^^^^^^^^^^^^
  File "/home/venture/Digital-Time-Capsule/journal_app/app/journal/routes.py", line 228, in edit_entry
    new_file = upload_file(file, upd_entry, False)
               ^^^^^^^^^^^^^^^^^^^^^^^^^^^^^^^^^^^
  File "/home/venture/.venvs/flask_env/lib/python3.11/site-packages/flask_login/utils.py", line 290, in decorated_view
    return current_app.ensure_sync(func)(*args, **kwargs)
           ^^^^^^^^^^^^^^^^^^^^^^^^^^^^^^^^^^^^^^^^^^^^^^
  File "/home/venture/Digital-Time-Capsule/journal_app/app/journal/routes.py", line 139, in upload_file
    os.mkdir(target_dir)
FileNotFoundError: [Errno 2] No such file or directory: '/static/uploads/winnie'
2025-05-10 05:25:41,625 ERROR: Exception on /journal/edit_entry/2 [POST] [in /home/venture/.venvs/flask_env/lib/python3.11/site-packages/flask/app.py:875]
Traceback (most recent call last):
  File "/home/venture/.venvs/flask_env/lib/python3.11/site-packages/flask/app.py", line 1511, in wsgi_app
    response = self.full_dispatch_request()
               ^^^^^^^^^^^^^^^^^^^^^^^^^^^^
  File "/home/venture/.venvs/flask_env/lib/python3.11/site-packages/flask/app.py", line 919, in full_dispatch_request
    rv = self.handle_user_exception(e)
         ^^^^^^^^^^^^^^^^^^^^^^^^^^^^^
  File "/home/venture/.venvs/flask_env/lib/python3.11/site-packages/flask/app.py", line 917, in full_dispatch_request
    rv = self.dispatch_request()
         ^^^^^^^^^^^^^^^^^^^^^^^
  File "/home/venture/.venvs/flask_env/lib/python3.11/site-packages/flask/app.py", line 902, in dispatch_request
    return self.ensure_sync(self.view_functions[rule.endpoint])(**view_args)  # type: ignore[no-any-return]
           ^^^^^^^^^^^^^^^^^^^^^^^^^^^^^^^^^^^^^^^^^^^^^^^^^^^^^^^^^^^^^^^^^
  File "/home/venture/.venvs/flask_env/lib/python3.11/site-packages/flask_login/utils.py", line 290, in decorated_view
    return current_app.ensure_sync(func)(*args, **kwargs)
           ^^^^^^^^^^^^^^^^^^^^^^^^^^^^^^^^^^^^^^^^^^^^^^
  File "/home/venture/Digital-Time-Capsule/journal_app/app/journal/routes.py", line 228, in edit_entry
    new_file = upload_file(file, upd_entry, False)
               ^^^^^^^^^^^^^^^^^^^^^^^^^^^^^^^^^^^
  File "/home/venture/.venvs/flask_env/lib/python3.11/site-packages/flask_login/utils.py", line 290, in decorated_view
    return current_app.ensure_sync(func)(*args, **kwargs)
           ^^^^^^^^^^^^^^^^^^^^^^^^^^^^^^^^^^^^^^^^^^^^^^
  File "/home/venture/Digital-Time-Capsule/journal_app/app/journal/routes.py", line 139, in upload_file
    os.mkdir(target_dir)
FileNotFoundError: [Errno 2] No such file or directory: '/static/uploads/winnie'
2025-05-10 05:25:54,868 ERROR: Exception on /journal/new_entry [POST] [in /home/venture/.venvs/flask_env/lib/python3.11/site-packages/flask/app.py:875]
Traceback (most recent call last):
  File "/home/venture/.venvs/flask_env/lib/python3.11/site-packages/flask/app.py", line 1511, in wsgi_app
    response = self.full_dispatch_request()
               ^^^^^^^^^^^^^^^^^^^^^^^^^^^^
  File "/home/venture/.venvs/flask_env/lib/python3.11/site-packages/flask/app.py", line 919, in full_dispatch_request
    rv = self.handle_user_exception(e)
         ^^^^^^^^^^^^^^^^^^^^^^^^^^^^^
  File "/home/venture/.venvs/flask_env/lib/python3.11/site-packages/flask/app.py", line 917, in full_dispatch_request
    rv = self.dispatch_request()
         ^^^^^^^^^^^^^^^^^^^^^^^
  File "/home/venture/.venvs/flask_env/lib/python3.11/site-packages/flask/app.py", line 902, in dispatch_request
    return self.ensure_sync(self.view_functions[rule.endpoint])(**view_args)  # type: ignore[no-any-return]
           ^^^^^^^^^^^^^^^^^^^^^^^^^^^^^^^^^^^^^^^^^^^^^^^^^^^^^^^^^^^^^^^^^
  File "/home/venture/.venvs/flask_env/lib/python3.11/site-packages/flask_login/utils.py", line 290, in decorated_view
    return current_app.ensure_sync(func)(*args, **kwargs)
           ^^^^^^^^^^^^^^^^^^^^^^^^^^^^^^^^^^^^^^^^^^^^^^
  File "/home/venture/Digital-Time-Capsule/journal_app/app/journal/routes.py", line 87, in new_entry
    if upload_file(file, new_entry) is None:
       ^^^^^^^^^^^^^^^^^^^^^^^^^^^^
  File "/home/venture/.venvs/flask_env/lib/python3.11/site-packages/flask_login/utils.py", line 290, in decorated_view
    return current_app.ensure_sync(func)(*args, **kwargs)
           ^^^^^^^^^^^^^^^^^^^^^^^^^^^^^^^^^^^^^^^^^^^^^^
  File "/home/venture/Digital-Time-Capsule/journal_app/app/journal/routes.py", line 139, in upload_file
    os.mkdir(target_dir)
FileNotFoundError: [Errno 2] No such file or directory: '/static/uploads/winnie'
2025-05-10 05:26:54,332 ERROR: Exception on /journal/edit_entry/2 [POST] [in /home/venture/.venvs/flask_env/lib/python3.11/site-packages/flask/app.py:875]
Traceback (most recent call last):
  File "/home/venture/.venvs/flask_env/lib/python3.11/site-packages/flask/app.py", line 1511, in wsgi_app
    response = self.full_dispatch_request()
               ^^^^^^^^^^^^^^^^^^^^^^^^^^^^
  File "/home/venture/.venvs/flask_env/lib/python3.11/site-packages/flask/app.py", line 919, in full_dispatch_request
    rv = self.handle_user_exception(e)
         ^^^^^^^^^^^^^^^^^^^^^^^^^^^^^
  File "/home/venture/.venvs/flask_env/lib/python3.11/site-packages/flask/app.py", line 917, in full_dispatch_request
    rv = self.dispatch_request()
         ^^^^^^^^^^^^^^^^^^^^^^^
  File "/home/venture/.venvs/flask_env/lib/python3.11/site-packages/flask/app.py", line 902, in dispatch_request
    return self.ensure_sync(self.view_functions[rule.endpoint])(**view_args)  # type: ignore[no-any-return]
           ^^^^^^^^^^^^^^^^^^^^^^^^^^^^^^^^^^^^^^^^^^^^^^^^^^^^^^^^^^^^^^^^^
  File "/home/venture/.venvs/flask_env/lib/python3.11/site-packages/flask_login/utils.py", line 290, in decorated_view
    return current_app.ensure_sync(func)(*args, **kwargs)
           ^^^^^^^^^^^^^^^^^^^^^^^^^^^^^^^^^^^^^^^^^^^^^^
  File "/home/venture/Digital-Time-Capsule/journal_app/app/journal/routes.py", line 228, in edit_entry
    new_file = upload_file(file, upd_entry, False)
               ^^^^^^^^^^^^^^^^^^^^^^^^^^^^^^^^^^^
  File "/home/venture/.venvs/flask_env/lib/python3.11/site-packages/flask_login/utils.py", line 290, in decorated_view
    return current_app.ensure_sync(func)(*args, **kwargs)
           ^^^^^^^^^^^^^^^^^^^^^^^^^^^^^^^^^^^^^^^^^^^^^^
  File "/home/venture/Digital-Time-Capsule/journal_app/app/journal/routes.py", line 139, in upload_file
    os.mkdir(target_dir)
FileNotFoundError: [Errno 2] No such file or directory: '/static/uploads/winnie'
2025-05-10 07:06:17,038 INFO: Digital-Journal-App startup [in /home/venture/Digital-Time-Capsule/journal_app/app/__init__.py:59]
